Workbook

Sheet cpus
A1: Producer | B1: CPU Name | C1: Processor Number | D1: Brand Modifier | E1: Intel® Core™ Gen | F1: # of Cores | G1: # of P-cores | H1: # of E-cores | I1: # of Threads | J1: Max Turbo Frequency (GHz) | K1: Performance-core Base Frequency (GHz) | L1: Efficient-core Base Frequency (GHz) | M1: Processor Base Frequency (GHz) | N1: Cache (MB) | O1: Processor Base Power (previously Thermal Design Power (TDP)) (W) | P1: Max Memory Size (dependent on memory type) GB | Q1: Memory Types (MT/s) | R1: Max # of PCI Express Lanes | S1: Supported Socket | T1: Processor Graphics | U1: Graphics Max Dynamic Frequency (GHz) | V1: Intel® Optane™ Memory Supported | W1: Intel® Turbo Boost Technology 2.0 | X1: Intel® Turbo Boost Max Technology 3.0 | Y1: Intel® vPro™ Platform Eligibility | Z1: Max Resolution for HDMI, Max Resolution for DP, Max Resolution for (eDP - Integrated Flat Panel) | AA1: Price
A2: Intel | B2: =TRIM(A2) & " Core " & TRIM(C2) -> Intel Core i9-14900KS | C2: i9-14900KS | D2: i9 | E2: 14th | F2: 24 | G2: 8 | H2: 16 | I2: 32 | J2: 6.2 | K2: 3.2 | L2: 2.4 | M2: N/A | N2: 36 | O2: 150 | P2: 192 | Q2: Up to DDR5 5600 MT/s Up to DDR4 3200 MT/s | R2: 20 | S2: LGA1700 | T2: UHD 770 | U2: 1.65 | V2: No | W2: Yes | X2: Yes | Y2: Yes | Z2: HDMI: 4096 x 2160 @ 60Hz DP: 7680 x 4320 @ 60Hz eDP: 5120 x 3200 @ 120Hz | AA2: =IFERROR(VLOOKUP(B2, Prices!A:I, 9, FALSE), "") -> 689.99
A3: Intel | B3: =TRIM(A3) & " Core " & TRIM(C3) -> Intel Core i9-14900F | C3: i9-14900F | D3: i9 | E3: 14th | F3: 24 | G3: 8 | H3: 16 | I3: 32 | J3: 5.8 | K3: 2 | L3: 1.5 | M3: N/A | N3: 36 | O3: 65 | P3: 192 | Q3: Up to DDR5 5600 MT/s Up to DDR4 3200 MT/s | R3: 20 | S3: LGA1700 | T3: No | U3: N/A | V3: No | W3: Yes | X3: Yes | Y3: No | Z3: N/A | AA3: =IFERROR(VLOOKUP(B3, Prices!A:I, 9, FALSE), "")
A4: Intel | B4: =TRIM(A4) & " Core " & TRIM(C4) -> Intel Core i9-14900 | C4: i9-14900 | D4: i9 | E4: 14th | F4: 24 | G4: 8 | H4: 16 | I4: 32 | J4: 5.8 | K4: 2 | L4: 1.5 | M4: N/A | N4: 36 | O4: 65 | P4: 192 | Q4: Up to DDR5 5600 MT/s Up to DDR4 3200 MT/s | R4: 20 | S4: LGA1700 | T4: UHD 770 | U4: 1.65 | V4: No | W4: Yes | X4: Yes | Y4: Yes | Z4: HDMI: 4096 x 2160 @ 60Hz DP: 7680 x 4320 @ 60Hz eDP: 5120 x 3200 @ 120Hz | AA4: =IFERROR(VLOOKUP(B4, Prices!A:I, 9, FALSE), "")
A5: Intel | B5: =TRIM(A5) & " Core " & TRIM(C5) -> Intel Core i9-14900T | C5: i9-14900T | D5: i9 | E5: 14th | F5: 24 | G5: 8 | H5: 16 | I5: 32 | J5: 5.5 | K5: 1.1 | L5: 0.8 | M5: N/A | N5: 36 | O5: 35 | P5: 192 | Q5: Up to DDR5 5600 MT/s Up to DDR4 3200 MT/s | R5: 20 | S5: LGA1700 | T5: UHD 770 | U5: 1.65 | V5: No | W5: Yes | X5: Yes | Y5: Yes | Z5: HDMI: 4096 x 2160 @ 60Hz DP: 7680 x 4320 @ 60Hz eDP: 5120 x 3200 @ 120Hz | AA5: =IFERROR(VLOOKUP(B5, Prices!A:I, 9, FALSE), "")
A6: Intel | B6: =TRIM(A6) & " Core " & TRIM(C6) -> Intel Core i7-14700F | C6: i7-14700F | D6: i7 | E6: 14th | F6: 20 | G6: 8 | H6: 12 | I6: 28 | J6: 5.4 | K6: 2.1 | L6: 1.5 | M6: N/A | N6: 33 | O6: 65 | P6: 192 | Q6: Up to DDR5 5600 MT/s Up to DDR4 3200 MT/s | R6: 20 | S6: LGA1700 | T6: No | U6: N/A | V6: No | W6: Yes | X6: Yes | Y6: No | Z6: N/A | AA6: =IFERROR(VLOOKUP(B6, Prices!A:I, 9, FALSE), "") -> 329.97
A7: Intel | B7: =TRIM(A7) & " Core " & TRIM(C7) -> Intel Core i7-14700T | C7: i7-14700T | D7: i7 | E7: 14th | F7: 20 | G7: 8 | H7: 12 | I7: 28 | J7: 5.2 | K7: 1.3 | L7: 0.9 | M7: N/A | N7: 33 | O7: 35 | P7: 192 | Q7: Up to DDR5 5600 MT/s Up to DDR4 3200 MT/s | R7: 20 | S7: LGA1700 | T7: UHD 770 | U7: 1.6 | V7: No | W7: Yes | X7: Yes | Y7: Yes | Z7: HDMI: 4096 x 2160 @ 60Hz DP: 7680 x 4320 @ 60Hz eDP: 5120 x 3200 @ 120Hz | AA7: =IFERROR(VLOOKUP(B7, Prices!A:I, 9, FALSE), "")
A8: Intel | B8: =TRIM(A8) & " Core " & TRIM(C8) -> Intel Core i7-14700 | C8: i7-14700 | D8: i7 | E8: 14th | F8: 20 | G8: 8 | H8: 12 | I8: 28 | J8: 5.4 | K8: 2.1 | L8: 1.5 | M8: N/A | N8: 33 | O8: 65 | P8: 192 | Q8: Up to DDR5 5600 MT/s Up to DDR4 3200 MT/s | R8: 20 | S8: LGA1700 | T8: UHD 770 | U8: 1.6 | V8: No | W8: Yes | X8: Yes | Y8: Yes | Z8: HDMI: 4096 x 2160 @ 60Hz DP: 7680 x 4320 @ 60Hz eDP: 5120 x 3200 @ 120Hz | AA8: =IFERROR(VLOOKUP(B8, Prices!A:I, 9, FALSE), "") -> 480.09
A9: Intel | B9: =TRIM(A9) & " Core " & TRIM(C9) -> Intel Core i5-14600 | C9: i5-14600 | D9: i5 | E9: 14th | F9: 14 | G9: 6 | H9: 8 | I9: 20 | J9: 5.2 | K9: 2.7 | L9: 2 | M9: N/A | N9: 24 | O9: 65 | P9: 192 | Q9: Up to DDR5 4800 MT/s Up to DDR4 3200 MT/s | R9: 20 | S9: LGA1700 | T9: UHD 770 | U9: 1.55 | V9: No | W9: Yes | X9: No | Y9: Yes | Z9: HDMI: 4096 x 2160 @ 60Hz DP: 7680 x 4320 @ 60Hz eDP: 5120 x 3200 @ 120Hz | AA9: =IFERROR(VLOOKUP(B9, Prices!A:I, 9, FALSE), "")
A10: Intel | B10: =TRIM(A10) & " Core " & TRIM(C10) -> Intel Core i5-14400T | C10: i5-14400T | D10: i5 | E10: 14th | F10: 10 | G10: 6 | H10: 4 | I10: 16 | J10: 4.5 | K10: 1.5 | L10: 1.1 | M10: N/A | N10: 20 | O10: 35 | P10: 192 | Q10: Up to DDR5 4800 MT/s Up to DDR4 3200 MT/s | R10: 20 | S10: LGA1700 | T10: UHD 730 | U10: 1.55 | V10: No | W10: Yes | X10: No | Y10: No | Z10: HDMI: 4096 x 2160 @ 60Hz DP: 7680 x 4320 @ 60Hz eDP: 5120 x 3200 @ 120Hz | AA10: =IFERROR(VLOOKUP(B10, Prices!A:I, 9, FALSE), "")
A11: Intel | B11: =TRIM(A11) & " Core " & TRIM(C11) -> Intel Core i5-14400 | C11: i5-14400 | D11: i5 | E11: 14th | F11: 10 | G11: 6 | H11: 4 | I11: 16 | J11: 4.7 | K11: 2.5 | L11: 1.8 | M11: N/A | N11: 20 | O11: 65 | P11: 192 | Q11: Up to DDR5 4800 MT/s Up to DDR4 3200 MT/s | R11: 20 | S11: LGA1700 | T11: UHD 730 | U11: 1.55 | V11: No | W11: Yes | X11: No | Y11: No | Z11: HDMI: 4096 x 2160 @ 60Hz DP: 7680 x 4320 @ 60Hz eDP: 5120 x 3200 @ 120Hz | AA11: =IFERROR(VLOOKUP(B11, Prices!A:I, 9, FALSE), "") -> 261.72
A12: Intel | B12: =TRIM(A12) & " Core " & TRIM(C12) -> Intel Core i5-14500 | C12: i5-14500 | D12: i5 | E12: 14th | F12: 14 | G12: 6 | H12: 8 | I12: 20 | J12: 5 | K12: 2.6 | L12: 1.9 | M12: N/A | N12: 24 | O12: 65 | P12: 192 | Q12: Up to DDR5 4800 MT/s Up to DDR4 3200 MT/s | R12: 20 | S12: LGA1700 | T12: UHD 770 | U12: 1.55 | V12: No | W12: Yes | X12: No | Y12: Yes | Z12: HDMI: 4096 x 2160 @ 60Hz DP: 7680 x 4320 @ 60Hz eDP: 5120 x 3200 @ 120Hz | AA12: =IFERROR(VLOOKUP(B12, Prices!A:I, 9, FALSE), "") -> 478.95
A13: Intel | B13: =TRIM(A13) & " Core " & TRIM(C13) -> Intel Core i5-14600T | C13: i5-14600T | D13: i5 | E13: 14th | F13: 14 | G13: 6 | H13: 8 | I13: 20 | J13: 5.1 | K13: 1.8 | L13: 1.3 | M13: N/A | N13: 24 | O13: 35 | P13: 192 | Q13: Up to DDR5 5600 MT/s Up to DDR4 3200 MT/s | R13: 20 | S13: LGA1700 | T13: UHD 770 | U13: 1.55 | V13: No | W13: Yes | X13: No | Y13: Yes | Z13: HDMI: 4096 x 2160 @ 60Hz DP: 7680 x 4320 @ 60Hz eDP: 5120 x 3200 @ 120Hz | AA13: =IFERROR(VLOOKUP(B13, Prices!A:I, 9, FALSE), "")
A14: Intel | B14: =TRIM(A14) & " Core " & TRIM(C14) -> Intel Core i5-14500T | C14: i5-14500T | D14: i5 | E14: 14th | F14: 14 | G14: 6 | H14: 8 | I14: 20 | J14: 4.8 | K14: 1.7 | L14: 1.2 | M14: N/A | N14: 24 | O14: 35 | P14: 192 | Q14: Up to DDR5 4800 MT/s Up to DDR4 3200 MT/s | R14: 20 | S14: LGA1700 | T14: UHD 770 | U14: 1.55 | V14: No | W14: Yes | X14: No | Y14: Yes | Z14: HDMI: 4096 x 2160 @ 60Hz DP: 7680 x 4320 @ 60Hz eDP: 5120 x 3200 @ 120Hz | AA14: =IFERROR(VLOOKUP(B14, Prices!A:I, 9, FALSE), "") -> 0
A15: Intel | B15: =TRIM(A15) & " Core " & TRIM(C15) -> Intel Core i5-14400F | C15: i5-14400F | D15: i5 | E15: 14th | F15: 10 | G15: 6 | H15: 4 | I15: 16 | J15: 4.7 | K15: 2.5 | L15: 1.8 | M15: N/A | N15: 20 | O15: 65 | P15: 192 | Q15: Up to DDR5 4800 MT/s Up to DDR4 3200 MT/s | R15: 20 | S15: LGA1700 | T15: No | U15: N/A | V15: No | W15: Yes | X15: No | Y15: No | Z15: N/A | AA15: =IFERROR(VLOOKUP(B15, Prices!A:I, 9, FALSE), "") -> 234.99
A16: Intel | B16: =TRIM(A16) & " Core " & TRIM(C16) -> Intel Core i3-14100F | C16: i3-14100F | D16: i3 | E16: 14th | F16: 4 | G16: 4 | H16: 0 | I16: 8 | J16: 4.7 | K16: 3.5 | L16: N/A | M16: N/A | N16: 12 | O16: 58 | P16: 192 | Q16: Up to DDR5 4800 MT/s Up to DDR4 3200 MT/s | R16: 20 | S16: LGA1700 | T16: No | U16: N/A | V16: No | W16: Yes | X16: No | Y16: No | Z16: N/A | AA16: =IFERROR(VLOOKUP(B16, Prices!A:I, 9, FALSE), "") -> 99
A17: Intel | B17: =TRIM(A17) & " Core " & TRIM(C17) -> Intel Core i3-14100T | C17: i3-14100T | D17: i3 | E17: 14th | F17: 4 | G17: 4 | H17: 0 | I17: 8 | J17: 4.4 | K17: 2.7 | L17: N/A | M17: N/A | N17: 12 | O17: 35 | P17: 192 | Q17: Up to DDR5 4800 MT/s Up to DDR4 3200 MT/s | R17: 20 | S17: LGA1700 | T17: UHD 730 | U17: 1.5 | V17: No | W17: Yes | X17: No | Y17: No | Z17: HDMI: 4096 x 2160 @ 60Hz DP: 7680 x 4320 @ 60Hz eDP: 5120 x 3200 @ 120Hz | AA17: =IFERROR(VLOOKUP(B17, Prices!A:I, 9, FALSE), "")
A18: Intel | B18: =TRIM(A18) & " Core " & TRIM(C18) -> Intel Core i3-14100 | C18: i3-14100 | D18: i3 | E18: 14th | F18: 4 | G18: 4 | H18: 0 | I18: 8 | J18: 4.7 | K18: 3.5 | L18: N/A | M18: N/A | N18: 12 | O18: 60 | P18: 192 | Q18: Up to DDR5 4800 MT/s Up to DDR4 3200 MT/s | R18: 20 | S18: LGA1700 | T18: UHD 730 | U18: 1.5 | V18: No | W18: Yes | X18: No | Y18: No | Z18: HDMI: 4096 x 2160 @ 60Hz DP: 7680 x 4320 @ 60Hz eDP: 5120 x 3200 @ 120Hz | AA18: =IFERROR(VLOOKUP(B18, Prices!A:I, 9, FALSE), "") -> 204.99
A19: Intel | B19: =TRIM(A19) & " Core " & TRIM(C19) -> Intel Core i9-14900K | C19: i9-14900K | D19: i9 | E19: 14th | F19: 24 | G19: 8 | H19: 16 | I19: 32 | J19: 6 | K19: 3.2 | L19: 2.4 | M19: N/A | N19: 36 | O19: 125 | P19: 192 | Q19: Up to DDR5 5600, Up to DDR4 3200 | R19: 20 | S19: LGA1700 | T19: UHD 770 | U19: 1.65 | V19: No | W19: Yes | X19: Yes | Y19: Yes | Z19: HDMI: 4096 x 2160 @ 60Hz DP: 7680 x 4320 @ 60Hz eDP: 5120 x 3200 @ 120Hz | AA19: =IFERROR(VLOOKUP(B19, Prices!A:I, 9, FALSE), "") -> 468.99
A20: Intel | B20: =TRIM(A20) & " Core " & TRIM(C20) -> Intel Core i9-14900KF | C20: i9-14900KF | D20: i9 | E20: 14th | F20: 24 | G20: 8 | H20: 16 | I20: 32 | J20: 6 | K20: 3.2 | L20: 2.4 | M20: N/A | N20: 36 | O20: 125 | P20: 192 | Q20: Up to DDR5 5600, Up to DDR4 3200 | R20: 20 | S20: LGA1700 | T20: No | U20: N/A | V20: No | W20: Yes | X20: Yes | Y20: No | Z20: N/A | AA20: =IFERROR(VLOOKUP(B20, Prices!A:I, 9, FALSE), "") -> 439.79
A21: Intel | B21: =TRIM(A21) & " Core " & TRIM(C21) -> Intel Core i7-14700K | C21: i7-14700K | D21: i7 | E21: 14th | F21: 20 | G21: 8 | H21: 12 | I21: 28 | J21: 5.6 | K21: 3.4 | L21: 2.5 | M21: N/A | N21: 33 | O21: 125 | P21: 192 | Q21: Up to DDR5 5600, Up to DDR4 3200 | R21: 20 | S21: LGA1700 | T21: UHD 770 | U21: 1.6 | V21: No | W21: Yes | X21: Yes | Y21: Yes | Z21: HDMI: 4096 x 2160 @ 60Hz DP: 7680 x 4320 @ 60Hz eDP: 5120 x 3200 @ 120Hz | AA21: =IFERROR(VLOOKUP(B21, Prices!A:I, 9, FALSE), "") -> 339.79
A22: Intel | B22: =TRIM(A22) & " Core " & TRIM(C22) -> Intel Core i7-14700KF | C22: i7-14700KF | D22: i7 | E22: 14th | F22: 20 | G22: 8 | H22: 12 | I22: 28 | J22: 5.6 | K22: 3.4 | L22: 2.5 | M22: N/A | N22: 33 | O22: 125 | P22: 192 | Q22: Up to DDR5 5600, Up to DDR4 3200 | R22: 20 | S22: LGA1700 | T22: No | U22: N/A | V22: No | W22: Yes | X22: Yes | Y22: No | Z22: N/A | AA22: =IFERROR(VLOOKUP(B22, Prices!A:I, 9, FALSE), "")
A23: Intel | B23: =TRIM(A23) & " Core " & TRIM(C23) -> Intel Core i5-14600K | C23: i5-14600K | D23: i5 | E23: 14th | F23: 14 | G23: 6 | H23: 8 | I23: 20 | J23: 5.3 | K23: 3.5 | L23: 2.6 | M23: N/A | N23: 24 | O23: 125 | P23: 192 | Q23: Up to DDR5 5600, Up to DDR4 3200 | R23: 20 | S23: LGA1700 | T23: UHD 770 | U23: 1.55 | V23: No | W23: Yes | X23: No | Y23: Yes | Z23: HDMI: 4096 x 2160 @ 60Hz DP: 7680 x 4320 @ 60Hz eDP: 5120 x 3200 @ 120Hz | AA23: =IFERROR(VLOOKUP(B23, Prices!A:I, 9, FALSE), "")
A24: Intel | B24: =TRIM(A24) & " Core " & TRIM(C24) -> Intel Core i5-14600KF | C24: i5-14600KF | D24: i5 | E24: 14th | F24: 14 | G24: 6 | H24: 8 | I24: 20 | J24: 5.3 | K24: 3.5 | L24: 2.6 | M24: N/A | N24: 24 | O24: 125 | P24: 192 | Q24: Up to DDR5 5600, Up to DDR4 3200 | R24: 20 | S24: LGA1700 | T24: No | U24: N/A | V24: No | W24: Yes | X24: No | Y24: No | Z24: N/A | AA24: =IFERROR(VLOOKUP(B24, Prices!A:I, 9, FALSE), "")
A25: Intel | B25: =TRIM(A25) & " Core " & TRIM(C25) -> Intel Core i9-13900KS | C25: i9-13900KS | D25: =LEFT(C25,2) -> i9 | E25: 13th | F25: 24 | G25: 8 | H25: 16 | I25: 32 | J25: 6 | K25: 3.2 | L25: 2.4 | M25: N/A | N25: 36 | O25: 150 | P25: 128 | Q25: Up to DDR5 5600 Up to DDR4 3200 | R25: 20 | S25: LGA1700 | T25: UHD 770 | U25: 1.65 | V25: No | W25: Yes | X25: Yes | Y25: Yes | Z25: HDMI: 4096 x 2160 @ 60Hz DP: 7680 x 4320 @ 60Hz eDP: 5120 x 3200 @ 120Hz | AA25: =IFERROR(VLOOKUP(B25, Prices!A:I, 9, FALSE), "") -> 707
A26: Intel | B26: =TRIM(A26) & " Core " & TRIM(C26) -> Intel Core i9-13900F | C26: i9-13900F | D26: =LEFT(C26,2) -> i9 | E26: 13th | F26: 24 | G26: 8 | H26: 16 | I26: 32 | J26: 5.6 | K26: 2 | L26: 1.5 | M26: N/A | N26: 36 | O26: 65 | P26: 128 | Q26: Up to DDR5 5600, Up to DDR4 3200 | R26: 20 | S26: LGA1700 | T26: No | U26: N/A | V26: No | W26: Yes | X26: Yes | Y26: No | Z26: N/A | AA26: =IFERROR(VLOOKUP(B26, Prices!A:I, 9, FALSE), "") -> 0
A27: Intel | B27: =TRIM(A27) & " Core " & TRIM(C27) -> Intel Core i9-13900 | C27: i9-13900 | D27: =LEFT(C27,2) -> i9 | E27: 13th | F27: 24 | G27: 8 | H27: 16 | I27: 32 | J27: 5.6 | K27: 2 | L27: 1.5 | M27: N/A | N27: 36 | O27: 65 | P27: 128 | Q27: Up to DDR5 5600, Up to DDR4 3200 | R27: 20 | S27: LGA1700 | T27: UHD 770 | U27: 1.65 | V27: No | W27: Yes | X27: Yes | Y27: Yes | Z27: HDMI: 4096 x 2160 @ 60Hz DP: 7680 x 4320 @ 60Hz eDP: 5120 x 3200 @ 120Hz | AA27: =IFERROR(VLOOKUP(B27, Prices!A:I, 9, FALSE), "")
A28: Intel | B28: =TRIM(A28) & " Core " & TRIM(C28) -> Intel Core i9-13900T | C28: i9-13900T | D28: =LEFT(C28,2) -> i9 | E28: 13th | F28: 24 | G28: 8 | H28: 16 | I28: 32 | J28: 5.3 | K28: 1.1 | L28: 0.8 | M28: N/A | N28: 36 | O28: 35 | P28: 128 | Q28: Up to DDR5 5600, Up to DDR4 3200 | R28: 20 | S28: LGA1700 | T28: UHD 770 | U28: 1.65 | V28: No | W28: Yes | X28: Yes | Y28: Yes | Z28: HDMI: 4096 x 2160 @ 60Hz DP: 7680 x 4320 @ 60Hz eDP: 5120 x 3200 @ 120Hz | AA28: =IFERROR(VLOOKUP(B28, Prices!A:I, 9, FALSE), "") -> 0
A29: Intel | B29: =TRIM(A29) & " Core " & TRIM(C29) -> Intel Core i7-13700F | C29: i7-13700F | D29: i7 | E29: 13th | F29: 16 | G29: 8 | H29: 8 | I29: 24 | J29: 5.2 | K29: 2.1 | L29: 1.5 | M29: N/A | N29: 30 | O29: 65 | P29: 128 | Q29: Up to DDR5 5600, Up to DDR4 3200 | R29: 20 | S29: LGA1700 | T29: No | U29: N/A | V29: No | W29: Yes | X29: Yes | Y29: No | Z29: N/A | AA29: =IFERROR(VLOOKUP(B29, Prices!A:I, 9, FALSE), "") -> 0
A30: Intel | B30: =TRIM(A30) & " Core " & TRIM(C30) -> Intel Core i7-13700 | C30: i7-13700 | D30: i7 | E30: 13th | F30: 16 | G30: 8 | H30: 8 | I30: 24 | J30: 5.2 | K30: 2.1 | L30: 1.5 | M30: N/A | N30: 30 | O30: 65 | P30: 128 | Q30: Up to DDR5 5600, Up to DDR4 3200 | R30: 20 | S30: LGA1700 | T30: UHD 770 | U30: 1.6 | V30: No | W30: Yes | X30: Yes | Y30: Yes | Z30: HDMI: 4096 x 2160 @ 60Hz DP: 7680 x 4320 @ 60Hz eDP: 5120 x 3200 @ 120Hz | AA30: =IFERROR(VLOOKUP(B30, Prices!A:I, 9, FALSE), "")
A31: Intel | B31: =TRIM(A31) & " Core " & TRIM(C31) -> Intel Core i7-13700T | C31: i7-13700T | D31: i7 | E31: 13th | F31: 16 | G31: 8 | H31: 8 | I31: 24 | J31: 4.9 | K31: 1.4 | L31: 1 | M31: N/A | N31: 30 | O31: 35 | P31: 128 | Q31: Up to DDR5 5600, Up to DDR4 3200 | R31: 20 | S31: LGA1700 | T31: UHD 770 | U31: 1.6 | V31: No | W31: Yes | X31: Yes | Y31: Yes | Z31: HDMI: 4096 x 2160 @ 60Hz DP: 7680 x 4320 @ 60Hz eDP: 5120 x 3200 @ 120Hz | AA31: =IFERROR(VLOOKUP(B31, Prices!A:I, 9, FALSE), "") -> 0
A32: Intel | B32: =TRIM(A32) & " Core " & TRIM(C32) -> Intel Core i5-13600 | C32: i5-13600 | D32: i5 | E32: 13th | F32: 14 | G32: 6 | H32: 8 | I32: 20 | J32: 5 | K32: 2.7 | L32: 2 | M32: N/A | N32: 24 | O32: 65 | P32: 128 | Q32: Up to DDR5 4800 Up to DDR4 3200 | R32: 20 | S32: LGA1700 | T32: UHD 770 | U32: 1.55 | V32: No | W32: Yes | X32: No | Y32: Yes | Z32: HDMI: 4096 x 2160 @ 60Hz DP: 7680 x 4320 @ 60Hz eDP: 5120 x 3200 @ 120Hz | AA32: =IFERROR(VLOOKUP(B32, Prices!A:I, 9, FALSE), "") -> 0
A33: Intel | B33: =TRIM(A33) & " Core " & TRIM(C33) -> Intel Core i5-13600T | C33: i5-13600T | D33: i5 | E33: 13th | F33: 14 | G33: 6 | H33: 8 | I33: 20 | J33: 4.8 | K33: 1.8 | L33: 1.3 | M33: N/A | N33: 24 | O33: 35 | P33: 128 | Q33: Up to DDR5 4800 Up to DDR4 3200 | R33: 20 | S33: LGA1700 | T33: UHD 770 | U33: 1.55 | V33: No | W33: Yes | X33: No | Y33: Yes | Z33: HDMI: 4096 x 2160 @ 60Hz DP: 7680 x 4320 @ 60Hz eDP: 5120 x 3200 @ 120Hz | AA33: =IFERROR(VLOOKUP(B33, Prices!A:I, 9, FALSE), "")
A34: Intel | B34: =TRIM(A34) & " Core " & TRIM(C34) -> Intel Core i5-13500 | C34: i5-13500 | D34: i5 | E34: 13th | F34: 14 | G34: 6 | H34: 8 | I34: 20 | J34: 4.8 | K34: 2.5 | L34: 1.8 | M34: N/A | N34: 24 | O34: 65 | P34: 128 | Q34: Up to DDR5 4800 Up to DDR4 3200 | R34: 20 | S34: LGA1700 | T34: UHD 770 | U34: 1.55 | V34: No | W34: Yes | X34: No | Y34: Yes | Z34: HDMI: 4096 x 2160 @ 60Hz DP: 7680 x 4320 @ 60Hz eDP: 5120 x 3200 @ 120Hz | AA34: =IFERROR(VLOOKUP(B34, Prices!A:I, 9, FALSE), "") -> 0
A35: Intel | B35: =TRIM(A35) & " Core " & TRIM(C35) -> Intel Core i5-13500T | C35: i5-13500T | D35: i5 | E35: 13th | F35: 14 | G35: 6 | H35: 8 | I35: 20 | J35: 4.6 | K35: 1.6 | L35: 1.2 | M35: N/A | N35: 24 | O35: 35 | P35: 128 | Q35: Up to DDR5 4800 Up to DDR4 3200 | R35: 20 | S35: LGA1700 | T35: UHD 770 | U35: 1.55 | V35: No | W35: Yes | X35: No | Y35: Yes | Z35: HDMI: 4096 x 2160 @ 60Hz DP: 7680 x 4320 @ 60Hz eDP: 5120 x 3200 @ 120Hz | AA35: =IFERROR(VLOOKUP(B35, Prices!A:I, 9, FALSE), "")
A36: Intel | B36: =TRIM(A36) & " Core " & TRIM(C36) -> Intel Core i5-13400F | C36: i5-13400F | D36: i5 | E36: 13th | F36: 10 | G36: 6 | H36: 4 | I36: 16 | J36: 4.6 | K36: 2.5 | L36: 1.8 | M36: N/A | N36: 20 | O36: 65 | P36: 128 | Q36: Up to DDR5 4800 Up to DDR4 3200 | R36: 20 | S36: LGA1700 | T36: No | U36: N/A | V36: No | W36: Yes | X36: No | Y36: No | Z36: N/A | AA36: =IFERROR(VLOOKUP(B36, Prices!A:I, 9, FALSE), "") -> 234.29
A37: Intel | B37: =TRIM(A37) & " Core " & TRIM(C37) -> Intel Core i5-13400 | C37: i5-13400 | D37: i5 | E37: 13th | F37: 10 | G37: 6 | H37: 4 | I37: 16 | J37: 4.6 | K37: 2.5 | L37: 1.8 | M37: N/A | N37: 20 | O37: 65 | P37: 128 | Q37: Up to DDR5 4800 Up to DDR4 3200 | R37: 20 | S37: LGA1700 | T37: UHD 730 | U37: 1.55 | V37: No | W37: Yes | X37: No | Y37: No | Z37: HDMI: 4096 x 2160 @ 60Hz DP: 7680 x 4320 @ 60Hz eDP: 5120 x 3200 @ 120Hz | AA37: =IFERROR(VLOOKUP(B37, Prices!A:I, 9, FALSE), "") -> 370.57
A38: Intel | B38: =TRIM(A38) & " Core " & TRIM(C38) -> Intel Core i5-13400T | C38: i5-13400T | D38: i5 | E38: 13th | F38: 10 | G38: 6 | H38: 4 | I38: 16 | J38: 4.4 | K38: 1.3 | L38: 1 | M38: N/A | N38: 20 | O38: 35 | P38: 128 | Q38: Up to DDR5 4800 Up to DDR4 3200 | R38: 20 | S38: LGA1700 | T38: UHD 730 | U38: 1.55 | V38: No | W38: Yes | X38: No | Y38: No | Z38: HDMI: 4096 x 2160 @ 60Hz DP: 7680 x 4320 @ 60Hz eDP: 5120 x 3200 @ 120Hz | AA38: =IFERROR(VLOOKUP(B38, Prices!A:I, 9, FALSE), "")
A39: Intel | B39: =TRIM(A39) & " Core " & TRIM(C39) -> Intel Core i9-13900K | C39: i9-13900K | D39: i9 | E39: 13th | F39: 24 | G39: 8 | H39: 16 | I39: 32 | J39: 5.8 | K39: 3 | L39: 2.2 | M39: N/A | N39: 36 | O39: 125 | P39: 128 | Q39: Up to DDR5 5600, Up to DDR4 3200 | R39: 20 | S39: LGA1700 | T39: UHD 770 | U39: 1.65 | V39: No | W39: Yes | X39: Yes | Y39: Yes | Z39: HDMI: 4096 x 2160 @ 60Hz DP: 7680 x 4320 @ 60Hz eDP: 5120 x 3200 @ 120Hz | AA39: =IFERROR(VLOOKUP(B39, Prices!A:I, 9, FALSE), "") -> 599.95
A40: Intel | B40: =TRIM(A40) & " Core " & TRIM(C40) -> Intel Core i9-13900KF | C40: i9-13900KF | D40: i9 | E40: 13th | F40: 24 | G40: 8 | H40: 16 | I40: 32 | J40: 5.8 | K40: 3 | L40: 2.2 | M40: N/A | N40: 36 | O40: 125 | P40: 128 | Q40: Up to DDR5 5600, Up to DDR4 3200 | R40: 20 | S40: LGA1700 | T40: No | U40: N/A | V40: No | W40: Yes | X40: Yes | Y40: No | Z40: N/A | AA40: =IFERROR(VLOOKUP(B40, Prices!A:I, 9, FALSE), "") -> 606.78
...

Sheet BIG
A1: [Quad CPU] | B1: [Dual CPU] | C1: Full | D1: Producer | G1: Model | I1: a | J1: Socket | K1: ClockSpeed | L1: TurboSpeed | M1: Cores | N1: Threads | O1: TDP | P1: ReleaseDate | Q1: SourceUrl | R1: =IF(COUNTIF(cpus!B:B, C1)>0, "found", "Missing") -> Missing | S1: =IF(COUNTIF(cpus!C:C, G1)>0, "found", "Missing") -> Missing
A2: =IF(COUNTIF(C2,"*Quad CPU]*"),"found","missing") -> missing | B2: =IF(COUNTIF(C2,"*[Dual CPU]*"),"found","missing") -> missing | C2: =SUBSTITUTE(SUBSTITUTE(SUBSTITUTE(SUBSTITUTE(SUBSTITUTE(I2," Dual Core","")," Quad Core","")," Quad-Core","")," Dual-Core","")," APU","") -> 686 Gen | D2: =IF(ISNUMBER(SEARCH("AMD",H2)),"AMD", IF(ISNUMBER(SEARCH("Intel",H2)),"Intel", IF(ISNUMBER(SEARCH("Apple",H2)),"Apple", IF(ISNUMBER(SEARCH("ARM",H2)),"ARM", IF(ISNUMBER(SEARCH("Google",H2)),"Google", IF(ISNUMBER(SEARCH("MediaTek",H2)),"MediaTek", IF(ISNUMBER(SEARCH("Qualcomm",H2)),"Qualcomm", IF(ISNUMBER(SEARCH("Samsung",H2)),"Samsung", IF(ISNUMBER(SEARCH("Snapdragon",H2)),"Snapdragon",""))))))))) | E2: =TRIM(SUBSTITUTE(SUBSTITUTE(SUBSTITUTE(SUBSTITUTE(SUBSTITUTE(SUBSTITUTE(SUBSTITUTE(SUBSTITUTE(SUBSTITUTE(H2, "Apple",""),"ARM",""),"Google",""),"MediaTek",""),"Qualcomm",""),"Samsung",""),"Snapdragon",""),"Intel",""),"AMD","")) -> 686 Gen | F2: =TRIM(SUBSTITUTE(SUBSTITUTE(SUBSTITUTE(SUBSTITUTE(SUBSTITUTE(SUBSTITUTE(SUBSTITUTE(SUBSTITUTE(SUBSTITUTE(E2, "Core2 Extreme",""),"Core2 Quad",""),"Core2 Duo",""),"Core",""), "Pentium Gold",""),"Pentium",""), "Xeon Platinum",""),"Xeon Gold",""),"Xeon Silver","")) -> 686 Gen | G2: =TRIM(SUBSTITUTE(F2,"Xeon","")) -> 686 Gen | H2: =IFERROR(LEFT(C2, SEARCH(" @", C2) - 1), C2) -> 686 Gen | I2: 686 Gen | M2: 1 | N2: 1 | O2: -1 W | P2: Q1 2009 | Q2: https://www.cpubenchmark.net/cpu.php?cpu=686 Gen&id=1495 | R2: =IF(COUNTIF(cpus!B:B, C2)>0, "found", "Missing") -> Missing | S2: =IF(COUNTIF(cpus!C:C, G2)>0, "found", "Missing") -> Missing
A3: =IF(COUNTIF(C3,"*Quad CPU]*"),"found","missing") -> missing | B3: =IF(COUNTIF(C3,"*[Dual CPU]*"),"found","missing") -> missing | C3: =SUBSTITUTE(SUBSTITUTE(SUBSTITUTE(SUBSTITUTE(SUBSTITUTE(I3," Dual Core","")," Quad Core","")," Quad-Core","")," Dual-Core","")," APU","") -> AArch64 | D3: =IF(ISNUMBER(SEARCH("AMD",H3)),"AMD", IF(ISNUMBER(SEARCH("Intel",H3)),"Intel", IF(ISNUMBER(SEARCH("Apple",H3)),"Apple", IF(ISNUMBER(SEARCH("ARM",H3)),"ARM", IF(ISNUMBER(SEARCH("Google",H3)),"Google", IF(ISNUMBER(SEARCH("MediaTek",H3)),"MediaTek", IF(ISNUMBER(SEARCH("Qualcomm",H3)),"Qualcomm", IF(ISNUMBER(SEARCH("Samsung",H3)),"Samsung", IF(ISNUMBER(SEARCH("Snapdragon",H3)),"Snapdragon",""))))))))) | E3: =TRIM(SUBSTITUTE(SUBSTITUTE(SUBSTITUTE(SUBSTITUTE(SUBSTITUTE(SUBSTITUTE(SUBSTITUTE(SUBSTITUTE(SUBSTITUTE(H3, "Apple",""),"ARM",""),"Google",""),"MediaTek",""),"Qualcomm",""),"Samsung",""),"Snapdragon",""),"Intel",""),"AMD","")) -> AArch64 | F3: =TRIM(SUBSTITUTE(SUBSTITUTE(SUBSTITUTE(SUBSTITUTE(SUBSTITUTE(SUBSTITUTE(SUBSTITUTE(SUBSTITUTE(SUBSTITUTE(E3, "Core2 Extreme",""),"Core2 Quad",""),"Core2 Duo",""),"Core",""), "Pentium Gold",""),"Pentium",""), "Xeon Platinum",""),"Xeon Gold",""),"Xeon Silver","")) -> AArch64 | G3: =TRIM(SUBSTITUTE(F3,"Xeon","")) -> AArch64 | H3: =IFERROR(LEFT(C3, SEARCH(" @", C3) - 1), C3) -> AArch64 | I3: AArch64 | K3: 1.3 GHz | M3: 4 | N3: 4 | P3: Q1 2024 | Q3: https://www.cpubenchmark.net/cpu.php?cpu=AArch64&id=5934 | R3: =IF(COUNTIF(cpus!B:B, C3)>0, "found", "Missing") -> Missing | S3: =IF(COUNTIF(cpus!C:C, G3)>0, "found", "Missing") -> Missing
A4: =IF(COUNTIF(C4,"*Quad CPU]*"),"found","missing") -> missing | B4: =IF(COUNTIF(C4,"*[Dual CPU]*"),"found","missing") -> missing | C4: =SUBSTITUTE(SUBSTITUTE(SUBSTITUTE(SUBSTITUTE(SUBSTITUTE(I4," Dual Core","")," Quad Core","")," Quad-Core","")," Dual-Core","")," APU","") -> AArch64 rev 2 (aarch64) | D4: =IF(ISNUMBER(SEARCH("AMD",H4)),"AMD", IF(ISNUMBER(SEARCH("Intel",H4)),"Intel", IF(ISNUMBER(SEARCH("Apple",H4)),"Apple", IF(ISNUMBER(SEARCH("ARM",H4)),"ARM", IF(ISNUMBER(SEARCH("Google",H4)),"Google", IF(ISNUMBER(SEARCH("MediaTek",H4)),"MediaTek", IF(ISNUMBER(SEARCH("Qualcomm",H4)),"Qualcomm", IF(ISNUMBER(SEARCH("Samsung",H4)),"Samsung", IF(ISNUMBER(SEARCH("Snapdragon",H4)),"Snapdragon",""))))))))) | E4: =TRIM(SUBSTITUTE(SUBSTITUTE(SUBSTITUTE(SUBSTITUTE(SUBSTITUTE(SUBSTITUTE(SUBSTITUTE(SUBSTITUTE(SUBSTITUTE(H4, "Apple",""),"ARM",""),"Google",""),"MediaTek",""),"Qualcomm",""),"Samsung",""),"Snapdragon",""),"Intel",""),"AMD","")) -> AArch64 rev 2 (aarch64) | F4: =TRIM(SUBSTITUTE(SUBSTITUTE(SUBSTITUTE(SUBSTITUTE(SUBSTITUTE(SUBSTITUTE(SUBSTITUTE(SUBSTITUTE(SUBSTITUTE(E4, "Core2 Extreme",""),"Core2 Quad",""),"Core2 Duo",""),"Core",""), "Pentium Gold",""),"Pentium",""), "Xeon Platinum",""),"Xeon Gold",""),"Xeon Silver","")) -> AArch64 rev 2 (aarch64) | G4: =TRIM(SUBSTITUTE(F4,"Xeon","")) -> AArch64 rev 2 (aarch64) | H4: =IFERROR(LEFT(C4, SEARCH(" @", C4) - 1), C4) -> AArch64 rev 2 (aarch64) | I4: AArch64 rev 2 (aarch64) | K4: 2.2 GHz | M4: 8 | N4: 8 | P4: Q1 2021 | Q4: https://www.cpubenchmark.net/cpu.php?cpu=AArch64 rev 2 (aarch64)&id=4017 | R4: =IF(COUNTIF(cpus!B:B, C4)>0, "found", "Missing") -> Missing | S4: =IF(COUNTIF(cpus!C:C, G4)>0, "found", "Missing") -> Missing
A5: =IF(COUNTIF(C5,"*Quad CPU]*"),"found","missing") -> missing | B5: =IF(COUNTIF(C5,"*[Dual CPU]*"),"found","missing") -> missing | C5: =SUBSTITUTE(SUBSTITUTE(SUBSTITUTE(SUBSTITUTE(SUBSTITUTE(I5," Dual Core","")," Quad Core","")," Quad-Core","")," Dual-Core","")," APU","") -> AArch64 rev 4 (aarch64) | D5: =IF(ISNUMBER(SEARCH("AMD",H5)),"AMD", IF(ISNUMBER(SEARCH("Intel",H5)),"Intel", IF(ISNUMBER(SEARCH("Apple",H5)),"Apple", IF(ISNUMBER(SEARCH("ARM",H5)),"ARM", IF(ISNUMBER(SEARCH("Google",H5)),"Google", IF(ISNUMBER(SEARCH("MediaTek",H5)),"MediaTek", IF(ISNUMBER(SEARCH("Qualcomm",H5)),"Qualcomm", IF(ISNUMBER(SEARCH("Samsung",H5)),"Samsung", IF(ISNUMBER(SEARCH("Snapdragon",H5)),"Snapdragon",""))))))))) | E5: =TRIM(SUBSTITUTE(SUBSTITUTE(SUBSTITUTE(SUBSTITUTE(SUBSTITUTE(SUBSTITUTE(SUBSTITUTE(SUBSTITUTE(SUBSTITUTE(H5, "Apple",""),"ARM",""),"Google",""),"MediaTek",""),"Qualcomm",""),"Samsung",""),"Snapdragon",""),"Intel",""),"AMD","")) -> AArch64 rev 4 (aarch64) | F5: =TRIM(SUBSTITUTE(SUBSTITUTE(SUBSTITUTE(SUBSTITUTE(SUBSTITUTE(SUBSTITUTE(SUBSTITUTE(SUBSTITUTE(SUBSTITUTE(E5, "Core2 Extreme",""),"Core2 Quad",""),"Core2 Duo",""),"Core",""), "Pentium Gold",""),"Pentium",""), "Xeon Platinum",""),"Xeon Gold",""),"Xeon Silver","")) -> AArch64 rev 4 (aarch64) | G5: =TRIM(SUBSTITUTE(F5,"Xeon","")) -> AArch64 rev 4 (aarch64) | H5: =IFERROR(LEFT(C5, SEARCH(" @", C5) - 1), C5) -> AArch64 rev 4 (aarch64) | I5: AArch64 rev 4 (aarch64) | K5: 2.1 GHz | M5: 8 | N5: 8 | P5: Q1 2021 | Q5: https://www.cpubenchmark.net/cpu.php?cpu=AArch64 rev 4 (aarch64)&id=3916 | R5: =IF(COUNTIF(cpus!B:B, C5)>0, "found", "Missing") -> Missing | S5: =IF(COUNTIF(cpus!C:C, G5)>0, "found", "Missing") -> Missing
A6: =IF(COUNTIF(C6,"*Quad CPU]*"),"found","missing") -> missing | B6: =IF(COUNTIF(C6,"*[Dual CPU]*"),"found","missing") -> missing | C6: =SUBSTITUTE(SUBSTITUTE(SUBSTITUTE(SUBSTITUTE(SUBSTITUTE(I6," Dual Core","")," Quad Core","")," Quad-Core","")," Dual-Core","")," APU","") -> AC8257V-WAB | D6: =IF(ISNUMBER(SEARCH("AMD",H6)),"AMD", IF(ISNUMBER(SEARCH("Intel",H6)),"Intel", IF(ISNUMBER(SEARCH("Apple",H6)),"Apple", IF(ISNUMBER(SEARCH("ARM",H6)),"ARM", IF(ISNUMBER(SEARCH("Google",H6)),"Google", IF(ISNUMBER(SEARCH("MediaTek",H6)),"MediaTek", IF(ISNUMBER(SEARCH("Qualcomm",H6)),"Qualcomm", IF(ISNUMBER(SEARCH("Samsung",H6)),"Samsung", IF(ISNUMBER(SEARCH("Snapdragon",H6)),"Snapdragon",""))))))))) | E6: =TRIM(SUBSTITUTE(SUBSTITUTE(SUBSTITUTE(SUBSTITUTE(SUBSTITUTE(SUBSTITUTE(SUBSTITUTE(SUBSTITUTE(SUBSTITUTE(H6, "Apple",""),"ARM",""),"Google",""),"MediaTek",""),"Qualcomm",""),"Samsung",""),"Snapdragon",""),"Intel",""),"AMD","")) -> AC8257V-WAB | F6: =TRIM(SUBSTITUTE(SUBSTITUTE(SUBSTITUTE(SUBSTITUTE(SUBSTITUTE(SUBSTITUTE(SUBSTITUTE(SUBSTITUTE(SUBSTITUTE(E6, "Core2 Extreme",""),"Core2 Quad",""),"Core2 Duo",""),"Core",""), "Pentium Gold",""),"Pentium",""), "Xeon Platinum",""),"Xeon Gold",""),"Xeon Silver","")) -> AC8257V-WAB | G6: =TRIM(SUBSTITUTE(F6,"Xeon","")) -> AC8257V-WAB | H6: =IFERROR(LEFT(C6, SEARCH(" @", C6) - 1), C6) -> AC8257V-WAB | I6: AC8257V-WAB | K6: 2.0 GHz | M6: 8 | N6: 8 | P6: Q1 2021 | Q6: https://www.cpubenchmark.net/cpu.php?cpu=AC8257V-WAB&id=3980 | R6: =IF(COUNTIF(cpus!B:B, C6)>0, "found", "Missing") -> Missing | S6: =IF(COUNTIF(cpus!C:C, G6)>0, "found", "Missing") -> Missing
A7: =IF(COUNTIF(C7,"*Quad CPU]*"),"found","missing") -> missing | B7: =IF(COUNTIF(C7,"*[Dual CPU]*"),"found","missing") -> missing | C7: =SUBSTITUTE(SUBSTITUTE(SUBSTITUTE(SUBSTITUTE(SUBSTITUTE(I7," Dual Core","")," Quad Core","")," Quad-Core","")," Dual-Core","")," APU","") -> AC8259V-WAB | D7: =IF(ISNUMBER(SEARCH("AMD",H7)),"AMD", IF(ISNUMBER(SEARCH("Intel",H7)),"Intel", IF(ISNUMBER(SEARCH("Apple",H7)),"Apple", IF(ISNUMBER(SEARCH("ARM",H7)),"ARM", IF(ISNUMBER(SEARCH("Google",H7)),"Google", IF(ISNUMBER(SEARCH("MediaTek",H7)),"MediaTek", IF(ISNUMBER(SEARCH("Qualcomm",H7)),"Qualcomm", IF(ISNUMBER(SEARCH("Samsung",H7)),"Samsung", IF(ISNUMBER(SEARCH("Snapdragon",H7)),"Snapdragon",""))))))))) | E7: =TRIM(SUBSTITUTE(SUBSTITUTE(SUBSTITUTE(SUBSTITUTE(SUBSTITUTE(SUBSTITUTE(SUBSTITUTE(SUBSTITUTE(SUBSTITUTE(H7, "Apple",""),"ARM",""),"Google",""),"MediaTek",""),"Qualcomm",""),"Samsung",""),"Snapdragon",""),"Intel",""),"AMD","")) -> AC8259V-WAB | F7: =TRIM(SUBSTITUTE(SUBSTITUTE(SUBSTITUTE(SUBSTITUTE(SUBSTITUTE(SUBSTITUTE(SUBSTITUTE(SUBSTITUTE(SUBSTITUTE(E7, "Core2 Extreme",""),"Core2 Quad",""),"Core2 Duo",""),"Core",""), "Pentium Gold",""),"Pentium",""), "Xeon Platinum",""),"Xeon Gold",""),"Xeon Silver","")) -> AC8259V-WAB | G7: =TRIM(SUBSTITUTE(F7,"Xeon","")) -> AC8259V-WAB | H7: =IFERROR(LEFT(C7, SEARCH(" @", C7) - 1), C7) -> AC8259V-WAB | I7: AC8259V-WAB | K7: 2.2 GHz | M7: 8 | N7: 8 | P7: Q1 2024 | Q7: https://www.cpubenchmark.net/cpu.php?cpu=AC8259V-WAB&id=5947 | R7: =IF(COUNTIF(cpus!B:B, C7)>0, "found", "Missing") -> Missing | S7: =IF(COUNTIF(cpus!C:C, G7)>0, "found", "Missing") -> Missing
A8: =IF(COUNTIF(C8,"*Quad CPU]*"),"found","missing") -> missing | B8: =IF(COUNTIF(C8,"*[Dual CPU]*"),"found","missing") -> missing | C8: =SUBSTITUTE(SUBSTITUTE(SUBSTITUTE(SUBSTITUTE(SUBSTITUTE(I8," Dual Core","")," Quad Core","")," Quad-Core","")," Dual-Core","")," APU","") -> Allwinner A133 | D8: =IF(ISNUMBER(SEARCH("AMD",H8)),"AMD", IF(ISNUMBER(SEARCH("Intel",H8)),"Intel", IF(ISNUMBER(SEARCH("Apple",H8)),"Apple", IF(ISNUMBER(SEARCH("ARM",H8)),"ARM", IF(ISNUMBER(SEARCH("Google",H8)),"Google", IF(ISNUMBER(SEARCH("MediaTek",H8)),"MediaTek", IF(ISNUMBER(SEARCH("Qualcomm",H8)),"Qualcomm", IF(ISNUMBER(SEARCH("Samsung",H8)),"Samsung", IF(ISNUMBER(SEARCH("Snapdragon",H8)),"Snapdragon",""))))))))) | E8: =TRIM(SUBSTITUTE(SUBSTITUTE(SUBSTITUTE(SUBSTITUTE(SUBSTITUTE(SUBSTITUTE(SUBSTITUTE(SUBSTITUTE(SUBSTITUTE(H8, "Apple",""),"ARM",""),"Google",""),"MediaTek",""),"Qualcomm",""),"Samsung",""),"Snapdragon",""),"Intel",""),"AMD","")) -> Allwinner A133 | F8: =TRIM(SUBSTITUTE(SUBSTITUTE(SUBSTITUTE(SUBSTITUTE(SUBSTITUTE(SUBSTITUTE(SUBSTITUTE(SUBSTITUTE(SUBSTITUTE(E8, "Core2 Extreme",""),"Core2 Quad",""),"Core2 Duo",""),"Core",""), "Pentium Gold",""),"Pentium",""), "Xeon Platinum",""),"Xeon Gold",""),"Xeon Silver","")) -> Allwinner A133 | G8: =TRIM(SUBSTITUTE(F8,"Xeon","")) -> Allwinner A133 | H8: =IFERROR(LEFT(C8, SEARCH(" @", C8) - 1), C8) -> Allwinner A133 | I8: Allwinner A133 | K8: 1.8 GHz | M8: 4 | N8: 4 | P8: Q2 2023 | Q8: https://www.cpubenchmark.net/cpu.php?cpu=Allwinner A133&id=5410 | R8: =IF(COUNTIF(cpus!B:B, C8)>0, "found", "Missing") -> Missing | S8: =IF(COUNTIF(cpus!C:C, G8)>0, "found", "Missing") -> Missing
A9: =IF(COUNTIF(C9,"*Quad CPU]*"),"found","missing") -> missing | B9: =IF(COUNTIF(C9,"*[Dual CPU]*"),"found","missing") -> missing | C9: =SUBSTITUTE(SUBSTITUTE(SUBSTITUTE(SUBSTITUTE(SUBSTITUTE(I9," Dual Core","")," Quad Core","")," Quad-Core","")," Dual-Core","")," APU","") -> Allwinner A333 | D9: =IF(ISNUMBER(SEARCH("AMD",H9)),"AMD", IF(ISNUMBER(SEARCH("Intel",H9)),"Intel", IF(ISNUMBER(SEARCH("Apple",H9)),"Apple", IF(ISNUMBER(SEARCH("ARM",H9)),"ARM", IF(ISNUMBER(SEARCH("Google",H9)),"Google", IF(ISNUMBER(SEARCH("MediaTek",H9)),"MediaTek", IF(ISNUMBER(SEARCH("Qualcomm",H9)),"Qualcomm", IF(ISNUMBER(SEARCH("Samsung",H9)),"Samsung", IF(ISNUMBER(SEARCH("Snapdragon",H9)),"Snapdragon",""))))))))) | E9: =TRIM(SUBSTITUTE(SUBSTITUTE(SUBSTITUTE(SUBSTITUTE(SUBSTITUTE(SUBSTITUTE(SUBSTITUTE(SUBSTITUTE(SUBSTITUTE(H9, "Apple",""),"ARM",""),"Google",""),"MediaTek",""),"Qualcomm",""),"Samsung",""),"Snapdragon",""),"Intel",""),"AMD","")) -> Allwinner A333 | F9: =TRIM(SUBSTITUTE(SUBSTITUTE(SUBSTITUTE(SUBSTITUTE(SUBSTITUTE(SUBSTITUTE(SUBSTITUTE(SUBSTITUTE(SUBSTITUTE(E9, "Core2 Extreme",""),"Core2 Quad",""),"Core2 Duo",""),"Core",""), "Pentium Gold",""),"Pentium",""), "Xeon Platinum",""),"Xeon Gold",""),"Xeon Silver","")) -> Allwinner A333 | G9: =TRIM(SUBSTITUTE(F9,"Xeon","")) -> Allwinner A333 | H9: =IFERROR(LEFT(C9, SEARCH(" @", C9) - 1), C9) -> Allwinner A333 | I9: Allwinner A333 | K9: 1.8 GHz | M9: 5 | N9: 5 | P9: Q4 2025 | Q9: https://www.cpubenchmark.net/cpu.php?cpu=Allwinner A333&id=6970 | R9: =IF(COUNTIF(cpus!B:B, C9)>0, "found", "Missing") -> Missing | S9: =IF(COUNTIF(cpus!C:C, G9)>0, "found", "Missing") -> Missing
A10: =IF(COUNTIF(C10,"*Quad CPU]*"),"found","missing") -> missing | B10: =IF(COUNTIF(C10,"*[Dual CPU]*"),"found","missing") -> missing | C10: =SUBSTITUTE(SUBSTITUTE(SUBSTITUTE(SUBSTITUTE(SUBSTITUTE(I10," Dual Core","")," Quad Core","")," Quad-Core","")," Dual-Core","")," APU","") -> Allwinner A523 | D10: =IF(ISNUMBER(SEARCH("AMD",H10)),"AMD", IF(ISNUMBER(SEARCH("Intel",H10)),"Intel", IF(ISNUMBER(SEARCH("Apple",H10)),"Apple", IF(ISNUMBER(SEARCH("ARM",H10)),"ARM", IF(ISNUMBER(SEARCH("Google",H10)),"Google", IF(ISNUMBER(SEARCH("MediaTek",H10)),"MediaTek", IF(ISNUMBER(SEARCH("Qualcomm",H10)),"Qualcomm", IF(ISNUMBER(SEARCH("Samsung",H10)),"Samsung", IF(ISNUMBER(SEARCH("Snapdragon",H10)),"Snapdragon",""))))))))) | E10: =TRIM(SUBSTITUTE(SUBSTITUTE(SUBSTITUTE(SUBSTITUTE(SUBSTITUTE(SUBSTITUTE(SUBSTITUTE(SUBSTITUTE(SUBSTITUTE(H10, "Apple",""),"ARM",""),"Google",""),"MediaTek",""),"Qualcomm",""),"Samsung",""),"Snapdragon",""),"Intel",""),"AMD","")) -> Allwinner A523 | F10: =TRIM(SUBSTITUTE(SUBSTITUTE(SUBSTITUTE(SUBSTITUTE(SUBSTITUTE(SUBSTITUTE(SUBSTITUTE(SUBSTITUTE(SUBSTITUTE(E10, "Core2 Extreme",""),"Core2 Quad",""),"Core2 Duo",""),"Core",""), "Pentium Gold",""),"Pentium",""), "Xeon Platinum",""),"Xeon Gold",""),"Xeon Silver","")) -> Allwinner A523 | G10: =TRIM(SUBSTITUTE(F10,"Xeon","")) -> Allwinner A523 | H10: =IFERROR(LEFT(C10, SEARCH(" @", C10) - 1), C10) -> Allwinner A523 | I10: Allwinner A523 | K10: 1.8 GHz | M10: 8 | N10: 8 | P10: Q3 2023 | Q10: https://www.cpubenchmark.net/cpu.php?cpu=Allwinner A523&id=5651 | R10: =IF(COUNTIF(cpus!B:B, C10)>0, "found", "Missing") -> Missing | S10: =IF(COUNTIF(cpus!C:C, G10)>0, "found", "Missing") -> Missing
A11: =IF(COUNTIF(C11,"*Quad CPU]*"),"found","missing") -> missing | B11: =IF(COUNTIF(C11,"*[Dual CPU]*"),"found","missing") -> missing | C11: =SUBSTITUTE(SUBSTITUTE(SUBSTITUTE(SUBSTITUTE(SUBSTITUTE(I11," Dual Core","")," Quad Core","")," Quad-Core","")," Dual-Core","")," APU","") -> Allwinner A527 | D11: =IF(ISNUMBER(SEARCH("AMD",H11)),"AMD", IF(ISNUMBER(SEARCH("Intel",H11)),"Intel", IF(ISNUMBER(SEARCH("Apple",H11)),"Apple", IF(ISNUMBER(SEARCH("ARM",H11)),"ARM", IF(ISNUMBER(SEARCH("Google",H11)),"Google", IF(ISNUMBER(SEARCH("MediaTek",H11)),"MediaTek", IF(ISNUMBER(SEARCH("Qualcomm",H11)),"Qualcomm", IF(ISNUMBER(SEARCH("Samsung",H11)),"Samsung", IF(ISNUMBER(SEARCH("Snapdragon",H11)),"Snapdragon",""))))))))) | E11: =TRIM(SUBSTITUTE(SUBSTITUTE(SUBSTITUTE(SUBSTITUTE(SUBSTITUTE(SUBSTITUTE(SUBSTITUTE(SUBSTITUTE(SUBSTITUTE(H11, "Apple",""),"ARM",""),"Google",""),"MediaTek",""),"Qualcomm",""),"Samsung",""),"Snapdragon",""),"Intel",""),"AMD","")) -> Allwinner A527 | F11: =TRIM(SUBSTITUTE(SUBSTITUTE(SUBSTITUTE(SUBSTITUTE(SUBSTITUTE(SUBSTITUTE(SUBSTITUTE(SUBSTITUTE(SUBSTITUTE(E11, "Core2 Extreme",""),"Core2 Quad",""),"Core2 Duo",""),"Core",""), "Pentium Gold",""),"Pentium",""), "Xeon Platinum",""),"Xeon Gold",""),"Xeon Silver","")) -> Allwinner A527 | G11: =TRIM(SUBSTITUTE(F11,"Xeon","")) -> Allwinner A527 | H11: =IFERROR(LEFT(C11, SEARCH(" @", C11) - 1), C11) -> Allwinner A527 | I11: Allwinner A527 | K11: 2.0 GHz | M11: 8 | N11: 8 | P11: Q3 2023 | Q11: https://www.cpubenchmark.net/cpu.php?cpu=Allwinner A527&id=5591 | R11: =IF(COUNTIF(cpus!B:B, C11)>0, "found", "Missing") -> Missing | S11: =IF(COUNTIF(cpus!C:C, G11)>0, "found", "Missing") -> Missing
A12: =IF(COUNTIF(C12,"*Quad CPU]*"),"found","missing") -> missing | B12: =IF(COUNTIF(C12,"*[Dual CPU]*"),"found","missing") -> missing | C12: =SUBSTITUTE(SUBSTITUTE(SUBSTITUTE(SUBSTITUTE(SUBSTITUTE(I12," Dual Core","")," Quad Core","")," Quad-Core","")," Dual-Core","")," APU","") -> Allwinner A733 | D12: =IF(ISNUMBER(SEARCH("AMD",H12)),"AMD", IF(ISNUMBER(SEARCH("Intel",H12)),"Intel", IF(ISNUMBER(SEARCH("Apple",H12)),"Apple", IF(ISNUMBER(SEARCH("ARM",H12)),"ARM", IF(ISNUMBER(SEARCH("Google",H12)),"Google", IF(ISNUMBER(SEARCH("MediaTek",H12)),"MediaTek", IF(ISNUMBER(SEARCH("Qualcomm",H12)),"Qualcomm", IF(ISNUMBER(SEARCH("Samsung",H12)),"Samsung", IF(ISNUMBER(SEARCH("Snapdragon",H12)),"Snapdragon",""))))))))) | E12: =TRIM(SUBSTITUTE(SUBSTITUTE(SUBSTITUTE(SUBSTITUTE(SUBSTITUTE(SUBSTITUTE(SUBSTITUTE(SUBSTITUTE(SUBSTITUTE(H12, "Apple",""),"ARM",""),"Google",""),"MediaTek",""),"Qualcomm",""),"Samsung",""),"Snapdragon",""),"Intel",""),"AMD","")) -> Allwinner A733 | F12: =TRIM(SUBSTITUTE(SUBSTITUTE(SUBSTITUTE(SUBSTITUTE(SUBSTITUTE(SUBSTITUTE(SUBSTITUTE(SUBSTITUTE(SUBSTITUTE(E12, "Core2 Extreme",""),"Core2 Quad",""),"Core2 Duo",""),"Core",""), "Pentium Gold",""),"Pentium",""), "Xeon Platinum",""),"Xeon Gold",""),"Xeon Silver","")) -> Allwinner A733 | G12: =TRIM(SUBSTITUTE(F12,"Xeon","")) -> Allwinner A733 | H12: =IFERROR(LEFT(C12, SEARCH(" @", C12) - 1), C12) -> Allwinner A733 | I12: Allwinner A733 | K12: 2.0 GHz | M12: 8 | N12: 8 | P12: Q1 2025 | Q12: https://www.cpubenchmark.net/cpu.php?cpu=Allwinner A733&id=6545 | R12: =IF(COUNTIF(cpus!B:B, C12)>0, "found", "Missing") -> Missing | S12: =IF(COUNTIF(cpus!C:C, G12)>0, "found", "Missing") -> Missing
A13: =IF(COUNTIF(C13,"*Quad CPU]*"),"found","missing") -> missing | B13: =IF(COUNTIF(C13,"*[Dual CPU]*"),"found","missing") -> missing | C13: =SUBSTITUTE(SUBSTITUTE(SUBSTITUTE(SUBSTITUTE(SUBSTITUTE(I13," Dual Core","")," Quad Core","")," Quad-Core","")," Dual-Core","")," APU","") -> Allwinner H618 | D13: =IF(ISNUMBER(SEARCH("AMD",H13)),"AMD", IF(ISNUMBER(SEARCH("Intel",H13)),"Intel", IF(ISNUMBER(SEARCH("Apple",H13)),"Apple", IF(ISNUMBER(SEARCH("ARM",H13)),"ARM", IF(ISNUMBER(SEARCH("Google",H13)),"Google", IF(ISNUMBER(SEARCH("MediaTek",H13)),"MediaTek", IF(ISNUMBER(SEARCH("Qualcomm",H13)),"Qualcomm", IF(ISNUMBER(SEARCH("Samsung",H13)),"Samsung", IF(ISNUMBER(SEARCH("Snapdragon",H13)),"Snapdragon",""))))))))) | E13: =TRIM(SUBSTITUTE(SUBSTITUTE(SUBSTITUTE(SUBSTITUTE(SUBSTITUTE(SUBSTITUTE(SUBSTITUTE(SUBSTITUTE(SUBSTITUTE(H13, "Apple",""),"ARM",""),"Google",""),"MediaTek",""),"Qualcomm",""),"Samsung",""),"Snapdragon",""),"Intel",""),"AMD","")) -> Allwinner H618 | F13: =TRIM(SUBSTITUTE(SUBSTITUTE(SUBSTITUTE(SUBSTITUTE(SUBSTITUTE(SUBSTITUTE(SUBSTITUTE(SUBSTITUTE(SUBSTITUTE(E13, "Core2 Extreme",""),"Core2 Quad",""),"Core2 Duo",""),"Core",""), "Pentium Gold",""),"Pentium",""), "Xeon Platinum",""),"Xeon Gold",""),"Xeon Silver","")) -> Allwinner H618 | G13: =TRIM(SUBSTITUTE(F13,"Xeon","")) -> Allwinner H618 | H13: =IFERROR(LEFT(C13, SEARCH(" @", C13) - 1), C13) -> Allwinner H618 | I13: Allwinner H618 | K13: 1.4 GHz | M13: 4 | N13: 4 | P13: Q2 2023 | Q13: https://www.cpubenchmark.net/cpu.php?cpu=Allwinner H618&id=5549 | R13: =IF(COUNTIF(cpus!B:B, C13)>0, "found", "Missing") -> Missing | S13: =IF(COUNTIF(cpus!C:C, G13)>0, "found", "Missing") -> Missing
A14: =IF(COUNTIF(C14,"*Quad CPU]*"),"found","missing") -> missing | B14: =IF(COUNTIF(C14,"*[Dual CPU]*"),"found","missing") -> missing | C14: =SUBSTITUTE(SUBSTITUTE(SUBSTITUTE(SUBSTITUTE(SUBSTITUTE(I14," Dual Core","")," Quad Core","")," Quad-Core","")," Dual-Core","")," APU","") -> Allwinner h728 | D14: =IF(ISNUMBER(SEARCH("AMD",H14)),"AMD", IF(ISNUMBER(SEARCH("Intel",H14)),"Intel", IF(ISNUMBER(SEARCH("Apple",H14)),"Apple", IF(ISNUMBER(SEARCH("ARM",H14)),"ARM", IF(ISNUMBER(SEARCH("Google",H14)),"Google", IF(ISNUMBER(SEARCH("MediaTek",H14)),"MediaTek", IF(ISNUMBER(SEARCH("Qualcomm",H14)),"Qualcomm", IF(ISNUMBER(SEARCH("Samsung",H14)),"Samsung", IF(ISNUMBER(SEARCH("Snapdragon",H14)),"Snapdragon",""))))))))) | E14: =TRIM(SUBSTITUTE(SUBSTITUTE(SUBSTITUTE(SUBSTITUTE(SUBSTITUTE(SUBSTITUTE(SUBSTITUTE(SUBSTITUTE(SUBSTITUTE(H14, "Apple",""),"ARM",""),"Google",""),"MediaTek",""),"Qualcomm",""),"Samsung",""),"Snapdragon",""),"Intel",""),"AMD","")) -> Allwinner h728 | F14: =TRIM(SUBSTITUTE(SUBSTITUTE(SUBSTITUTE(SUBSTITUTE(SUBSTITUTE(SUBSTITUTE(SUBSTITUTE(SUBSTITUTE(SUBSTITUTE(E14, "Core2 Extreme",""),"Core2 Quad",""),"Core2 Duo",""),"Core",""), "Pentium Gold",""),"Pentium",""), "Xeon Platinum",""),"Xeon Gold",""),"Xeon Silver","")) -> Allwinner h728 | G14: =TRIM(SUBSTITUTE(F14,"Xeon","")) -> Allwinner h728 | H14: =IFERROR(LEFT(C14, SEARCH(" @", C14) - 1), C14) -> Allwinner h728 | I14: Allwinner h728 | K14: 1.8 GHz | M14: 8 | N14: 8 | P14: Q4 2024 | Q14: https://www.cpubenchmark.net/cpu.php?cpu=Allwinner h728&id=6316 | R14: =IF(COUNTIF(cpus!B:B, C14)>0, "found", "Missing") -> Missing | S14: =IF(COUNTIF(cpus!C:C, G14)>0, "found", "Missing") -> Missing
A15: =IF(COUNTIF(C15,"*Quad CPU]*"),"found","missing") -> missing | B15: =IF(COUNTIF(C15,"*[Dual CPU]*"),"found","missing") -> missing | C15: =SUBSTITUTE(SUBSTITUTE(SUBSTITUTE(SUBSTITUTE(SUBSTITUTE(I15," Dual Core","")," Quad Core","")," Quad-Core","")," Dual-Core","")," APU","") -> AMD 3015Ce | D15: =IF(ISNUMBER(SEARCH("AMD",H15)),"AMD", IF(ISNUMBER(SEARCH("Intel",H15)),"Intel", IF(ISNUMBER(SEARCH("Apple",H15)),"Apple", IF(ISNUMBER(SEARCH("ARM",H15)),"ARM", IF(ISNUMBER(SEARCH("Google",H15)),"Google", IF(ISNUMBER(SEARCH("MediaTek",H15)),"MediaTek", IF(ISNUMBER(SEARCH("Qualcomm",H15)),"Qualcomm", IF(ISNUMBER(SEARCH("Samsung",H15)),"Samsung", IF(ISNUMBER(SEARCH("Snapdragon",H15)),"Snapdragon",""))))))))) | E15: =TRIM(SUBSTITUTE(SUBSTITUTE(SUBSTITUTE(SUBSTITUTE(SUBSTITUTE(SUBSTITUTE(SUBSTITUTE(SUBSTITUTE(SUBSTITUTE(H15, "Apple",""),"ARM",""),"Google",""),"MediaTek",""),"Qualcomm",""),"Samsung",""),"Snapdragon",""),"Intel",""),"AMD","")) -> Zen 3 | F15: =TRIM(SUBSTITUTE(SUBSTITUTE(SUBSTITUTE(SUBSTITUTE(SUBSTITUTE(SUBSTITUTE(SUBSTITUTE(SUBSTITUTE(SUBSTITUTE(E15, "Core2 Extreme",""),"Core2 Quad",""),"Core2 Duo",""),"Core",""), "Pentium Gold",""),"Pentium",""), "Xeon Platinum",""),"Xeon Gold",""),"Xeon Silver","")) -> Zen 3 | G15: =TRIM(SUBSTITUTE(F15,"Xeon","")) -> Zen 3 | H15: =[1]cpu_pricesV2!$E$10 -> Zen 3 | I15: AMD 3015Ce | J15: FT5 | K15: 1.2 GHz | L15: 2.3 GHz | M15: 2 | N15: 4 | O15: 6 W | P15: Q3 2021 | Q15: https://www.cpubenchmark.net/cpu.php?cpu=AMD 3015Ce&id=4455 | R15: =IF(COUNTIF(cpus!B:B, C15)>0, "found", "Missing") -> found | S15: =IF(COUNTIF(cpus!C:C, G15)>0, "found", "Missing") -> Missing
A16: =IF(COUNTIF(C16,"*Quad CPU]*"),"found","missing") -> missing | B16: =IF(COUNTIF(C16,"*[Dual CPU]*"),"found","missing") -> missing | C16: =SUBSTITUTE(SUBSTITUTE(SUBSTITUTE(SUBSTITUTE(Load!R2," Quad Core","")," Quad-Core","")," Dual-Core","")," APU","") -> 6 | D16: =IF(ISNUMBER(SEARCH("AMD",H16)),"AMD", IF(ISNUMBER(SEARCH("Intel",H16)),"Intel", IF(ISNUMBER(SEARCH("Apple",H16)),"Apple", IF(ISNUMBER(SEARCH("ARM",H16)),"ARM", IF(ISNUMBER(SEARCH("Google",H16)),"Google", IF(ISNUMBER(SEARCH("MediaTek",H16)),"MediaTek", IF(ISNUMBER(SEARCH("Qualcomm",H16)),"Qualcomm", IF(ISNUMBER(SEARCH("Samsung",H16)),"Samsung", IF(ISNUMBER(SEARCH("Snapdragon",H16)),"Snapdragon",""))))))))) | E16: =TRIM(SUBSTITUTE(SUBSTITUTE(SUBSTITUTE(SUBSTITUTE(SUBSTITUTE(SUBSTITUTE(SUBSTITUTE(SUBSTITUTE(SUBSTITUTE(H16, "Apple",""),"ARM",""),"Google",""),"MediaTek",""),"Qualcomm",""),"Samsung",""),"Snapdragon",""),"Intel",""),"AMD","")) -> 6 | F16: =TRIM(SUBSTITUTE(SUBSTITUTE(SUBSTITUTE(SUBSTITUTE(SUBSTITUTE(SUBSTITUTE(SUBSTITUTE(SUBSTITUTE(SUBSTITUTE(E16, "Core2 Extreme",""),"Core2 Quad",""),"Core2 Duo",""),"Core",""), "Pentium Gold",""),"Pentium",""), "Xeon Platinum",""),"Xeon Gold",""),"Xeon Silver","")) -> 6 | G16: =TRIM(SUBSTITUTE(F16,"Xeon","")) -> 6 | H16: =IFERROR(LEFT(C16, SEARCH(" @", C16) - 1), C16) -> 6 | I16: AMD 3015e | K16: 1.2 GHz | L16: 2.3 GHz | M16: 2 | N16: 4 | O16: 6 W | P16: Q3 2020 | Q16: https://www.cpubenchmark.net/cpu.php?cpu=AMD 3015e&id=3774 | R16: =IF(COUNTIF(cpus!B:B, C16)>0, "found", "Missing") -> found | S16: =IF(COUNTIF(cpus!C:C, G16)>0, "found", "Missing") -> Missing
A17: =IF(COUNTIF(C17,"*Quad CPU]*"),"found","missing") -> missing | B17: =IF(COUNTIF(C17,"*[Dual CPU]*"),"found","missing") -> missing | C17: =SUBSTITUTE(SUBSTITUTE(SUBSTITUTE(SUBSTITUTE(SUBSTITUTE(I17," Dual Core","")," Quad Core","")," Quad-Core","")," Dual-Core","")," APU","") -> AMD 3020e | D17: =IF(ISNUMBER(SEARCH("AMD",H17)),"AMD", IF(ISNUMBER(SEARCH("Intel",H17)),"Intel", IF(ISNUMBER(SEARCH("Apple",H17)),"Apple", IF(ISNUMBER(SEARCH("ARM",H17)),"ARM", IF(ISNUMBER(SEARCH("Google",H17)),"Google", IF(ISNUMBER(SEARCH("MediaTek",H17)),"MediaTek", IF(ISNUMBER(SEARCH("Qualcomm",H17)),"Qualcomm", IF(ISNUMBER(SEARCH("Samsung",H17)),"Samsung", IF(ISNUMBER(SEARCH("Snapdragon",H17)),"Snapdragon",""))))))))) -> AMD | E17: =TRIM(SUBSTITUTE(SUBSTITUTE(SUBSTITUTE(SUBSTITUTE(SUBSTITUTE(SUBSTITUTE(SUBSTITUTE(SUBSTITUTE(SUBSTITUTE(H17, "Apple",""),"ARM",""),"Google",""),"MediaTek",""),"Qualcomm",""),"Samsung",""),"Snapdragon",""),"Intel",""),"AMD","")) -> 3020e | F17: =TRIM(SUBSTITUTE(SUBSTITUTE(SUBSTITUTE(SUBSTITUTE(SUBSTITUTE(SUBSTITUTE(SUBSTITUTE(SUBSTITUTE(SUBSTITUTE(E17, "Core2 Extreme",""),"Core2 Quad",""),"Core2 Duo",""),"Core",""), "Pentium Gold",""),"Pentium",""), "Xeon Platinum",""),"Xeon Gold",""),"Xeon Silver","")) -> 3020e | G17: =TRIM(SUBSTITUTE(F17,"Xeon","")) -> 3020e | H17: =IFERROR(LEFT(C17, SEARCH(" @", C17) - 1), C17) -> AMD 3020e | I17: AMD 3020e | K17: 1.2 GHz | L17: 2.6 GHz | M17: 2 | N17: 2 | O17: 6 W | P17: Q2 2020 | Q17: https://www.cpubenchmark.net/cpu.php?cpu=AMD 3020e&id=3758 | R17: =IF(COUNTIF(cpus!B:B, C17)>0, "found", "Missing") -> found | S17: =IF(COUNTIF(cpus!C:C, G17)>0, "found", "Missing") -> found
A18: =IF(COUNTIF(C18,"*Quad CPU]*"),"found","missing") -> missing | B18: =IF(COUNTIF(C18,"*[Dual CPU]*"),"found","missing") -> missing | C18: =SUBSTITUTE(SUBSTITUTE(SUBSTITUTE(SUBSTITUTE(SUBSTITUTE(I18," Dual Core","")," Quad Core","")," Quad-Core","")," Dual-Core","")," APU","") -> AMD 4700S | D18: =IF(ISNUMBER(SEARCH("AMD",H18)),"AMD", IF(ISNUMBER(SEARCH("Intel",H18)),"Intel", IF(ISNUMBER(SEARCH("Apple",H18)),"Apple", IF(ISNUMBER(SEARCH("ARM",H18)),"ARM", IF(ISNUMBER(SEARCH("Google",H18)),"Google", IF(ISNUMBER(SEARCH("MediaTek",H18)),"MediaTek", IF(ISNUMBER(SEARCH("Qualcomm",H18)),"Qualcomm", IF(ISNUMBER(SEARCH("Samsung",H18)),"Samsung", IF(ISNUMBER(SEARCH("Snapdragon",H18)),"Snapdragon",""))))))))) -> AMD | E18: =TRIM(SUBSTITUTE(SUBSTITUTE(SUBSTITUTE(SUBSTITUTE(SUBSTITUTE(SUBSTITUTE(SUBSTITUTE(SUBSTITUTE(SUBSTITUTE(H18, "Apple",""),"ARM",""),"Google",""),"MediaTek",""),"Qualcomm",""),"Samsung",""),"Snapdragon",""),"Intel",""),"AMD","")) -> 4700S | F18: =TRIM(SUBSTITUTE(SUBSTITUTE(SUBSTITUTE(SUBSTITUTE(SUBSTITUTE(SUBSTITUTE(SUBSTITUTE(SUBSTITUTE(SUBSTITUTE(E18, "Core2 Extreme",""),"Core2 Quad",""),"Core2 Duo",""),"Core",""), "Pentium Gold",""),"Pentium",""), "Xeon Platinum",""),"Xeon Gold",""),"Xeon Silver","")) -> 4700S | G18: =TRIM(SUBSTITUTE(F18,"Xeon","")) -> 4700S | H18: =IFERROR(LEFT(C18, SEARCH(" @", C18) - 1), C18) -> AMD 4700S | I18: AMD 4700S | K18: 3.6 GHz | L18: 4.0 GHz | M18: 8 | N18: 16 | P18: Q2 2021 | Q18: https://www.cpubenchmark.net/cpu.php?cpu=AMD 4700S&id=4309 | R18: =IF(COUNTIF(cpus!B:B, C18)>0, "found", "Missing") -> found | S18: =IF(COUNTIF(cpus!C:C, G18)>0, "found", "Missing") -> found
A19: =IF(COUNTIF(C19,"*Quad CPU]*"),"found","missing") -> missing | B19: =IF(COUNTIF(C19,"*[Dual CPU]*"),"found","missing") -> missing | C19: =SUBSTITUTE(SUBSTITUTE(SUBSTITUTE(SUBSTITUTE(SUBSTITUTE(I19," Dual Core","")," Quad Core","")," Quad-Core","")," Dual-Core","")," APU","") -> AMD A10 Micro-6700T | D19: =IF(ISNUMBER(SEARCH("AMD",H19)),"AMD", IF(ISNUMBER(SEARCH("Intel",H19)),"Intel", IF(ISNUMBER(SEARCH("Apple",H19)),"Apple", IF(ISNUMBER(SEARCH("ARM",H19)),"ARM", IF(ISNUMBER(SEARCH("Google",H19)),"Google", IF(ISNUMBER(SEARCH("MediaTek",H19)),"MediaTek", IF(ISNUMBER(SEARCH("Qualcomm",H19)),"Qualcomm", IF(ISNUMBER(SEARCH("Samsung",H19)),"Samsung", IF(ISNUMBER(SEARCH("Snapdragon",H19)),"Snapdragon",""))))))))) -> AMD | E19: =TRIM(SUBSTITUTE(SUBSTITUTE(SUBSTITUTE(SUBSTITUTE(SUBSTITUTE(SUBSTITUTE(SUBSTITUTE(SUBSTITUTE(SUBSTITUTE(H19, "Apple",""),"ARM",""),"Google",""),"MediaTek",""),"Qualcomm",""),"Samsung",""),"Snapdragon",""),"Intel",""),"AMD","")) -> A10 Micro-6700T | F19: =TRIM(SUBSTITUTE(SUBSTITUTE(SUBSTITUTE(SUBSTITUTE(SUBSTITUTE(SUBSTITUTE(SUBSTITUTE(SUBSTITUTE(SUBSTITUTE(E19, "Core2 Extreme",""),"Core2 Quad",""),"Core2 Duo",""),"Core",""), "Pentium Gold",""),"Pentium",""), "Xeon Platinum",""),"Xeon Gold",""),"Xeon Silver","")) -> A10 Micro-6700T | G19: =TRIM(SUBSTITUTE(F19,"Xeon","")) -> A10 Micro-6700T | H19: =IFERROR(LEFT(C19, SEARCH(" @", C19) - 1), C19) -> AMD A10 Micro-6700T | I19: AMD A10 Micro-6700T APU | J19: FT3b | K19: 1.2 GHz | L19: 2.2 GHz | M19: 4 | N19: 4 | O19: 5 W | P19: Q2 2015 | Q19: https://www.cpubenchmark.net/cpu.php?cpu=AMD A10 Micro-6700T APU&id=2520 | R19: =IF(COUNTIF(cpus!B:B, C19)>0, "found", "Missing") -> found | S19: =IF(COUNTIF(cpus!C:C, G19)>0, "found", "Missing") -> found
A20: =IF(COUNTIF(C20,"*Quad CPU]*"),"found","missing") -> missing | B20: =IF(COUNTIF(C20,"*[Dual CPU]*"),"found","missing") -> missing | C20: =SUBSTITUTE(SUBSTITUTE(SUBSTITUTE(SUBSTITUTE(SUBSTITUTE(I20," Dual Core","")," Quad Core","")," Quad-Core","")," Dual-Core","")," APU","") -> AMD A10 PRO-7350B | D20: =IF(ISNUMBER(SEARCH("AMD",H20)),"AMD", IF(ISNUMBER(SEARCH("Intel",H20)),"Intel", IF(ISNUMBER(SEARCH("Apple",H20)),"Apple", IF(ISNUMBER(SEARCH("ARM",H20)),"ARM", IF(ISNUMBER(SEARCH("Google",H20)),"Google", IF(ISNUMBER(SEARCH("MediaTek",H20)),"MediaTek", IF(ISNUMBER(SEARCH("Qualcomm",H20)),"Qualcomm", IF(ISNUMBER(SEARCH("Samsung",H20)),"Samsung", IF(ISNUMBER(SEARCH("Snapdragon",H20)),"Snapdragon",""))))))))) -> AMD | E20: =TRIM(SUBSTITUTE(SUBSTITUTE(SUBSTITUTE(SUBSTITUTE(SUBSTITUTE(SUBSTITUTE(SUBSTITUTE(SUBSTITUTE(SUBSTITUTE(H20, "Apple",""),"ARM",""),"Google",""),"MediaTek",""),"Qualcomm",""),"Samsung",""),"Snapdragon",""),"Intel",""),"AMD","")) -> A10 PRO-7350B | F20: =TRIM(SUBSTITUTE(SUBSTITUTE(SUBSTITUTE(SUBSTITUTE(SUBSTITUTE(SUBSTITUTE(SUBSTITUTE(SUBSTITUTE(SUBSTITUTE(E20, "Core2 Extreme",""),"Core2 Quad",""),"Core2 Duo",""),"Core",""), "Pentium Gold",""),"Pentium",""), "Xeon Platinum",""),"Xeon Gold",""),"Xeon Silver","")) -> A10 PRO-7350B | G20: =TRIM(SUBSTITUTE(F20,"Xeon","")) -> A10 PRO-7350B | H20: =IFERROR(LEFT(C20, SEARCH(" @", C20) - 1), C20) -> AMD A10 PRO-7350B | I20: AMD A10 PRO-7350B APU | J20: FP3 | K20: 2.1 GHz | L20: 3.3 GHz | M20: 4 | O20: 19 W | P20: Q2 2014 | Q20: https://www.cpubenchmark.net/cpu.php?cpu=AMD A10 PRO-7350B APU&id=2271 | R20: =IF(COUNTIF(cpus!B:B, C20)>0, "found", "Missing") -> found | S20: =IF(COUNTIF(cpus!C:C, G20)>0, "found", "Missing") -> found
A21: =IF(COUNTIF(C21,"*Quad CPU]*"),"found","missing") -> missing | B21: =IF(COUNTIF(C21,"*[Dual CPU]*"),"found","missing") -> missing | C21: =SUBSTITUTE(SUBSTITUTE(SUBSTITUTE(SUBSTITUTE(SUBSTITUTE(I21," Dual Core","")," Quad Core","")," Quad-Core","")," Dual-Core","")," APU","") -> AMD A10 PRO-7800B | D21: =IF(ISNUMBER(SEARCH("AMD",H21)),"AMD", IF(ISNUMBER(SEARCH("Intel",H21)),"Intel", IF(ISNUMBER(SEARCH("Apple",H21)),"Apple", IF(ISNUMBER(SEARCH("ARM",H21)),"ARM", IF(ISNUMBER(SEARCH("Google",H21)),"Google", IF(ISNUMBER(SEARCH("MediaTek",H21)),"MediaTek", IF(ISNUMBER(SEARCH("Qualcomm",H21)),"Qualcomm", IF(ISNUMBER(SEARCH("Samsung",H21)),"Samsung", IF(ISNUMBER(SEARCH("Snapdragon",H21)),"Snapdragon",""))))))))) -> AMD | E21: =TRIM(SUBSTITUTE(SUBSTITUTE(SUBSTITUTE(SUBSTITUTE(SUBSTITUTE(SUBSTITUTE(SUBSTITUTE(SUBSTITUTE(SUBSTITUTE(H21, "Apple",""),"ARM",""),"Google",""),"MediaTek",""),"Qualcomm",""),"Samsung",""),"Snapdragon",""),"Intel",""),"AMD","")) -> A10 PRO-7800B | F21: =TRIM(SUBSTITUTE(SUBSTITUTE(SUBSTITUTE(SUBSTITUTE(SUBSTITUTE(SUBSTITUTE(SUBSTITUTE(SUBSTITUTE(SUBSTITUTE(E21, "Core2 Extreme",""),"Core2 Quad",""),"Core2 Duo",""),"Core",""), "Pentium Gold",""),"Pentium",""), "Xeon Platinum",""),"Xeon Gold",""),"Xeon Silver","")) -> A10 PRO-7800B | G21: =TRIM(SUBSTITUTE(F21,"Xeon","")) -> A10 PRO-7800B | H21: =IFERROR(LEFT(C21, SEARCH(" @", C21) - 1), C21) -> AMD A10 PRO-7800B | I21: AMD A10 PRO-7800B APU | J21: FM2+ | K21: 3.5 GHz | L21: 3.9 GHz | M21: 4 | O21: 65 W | P21: Q4 2014 | Q21: https://www.cpubenchmark.net/cpu.php?cpu=AMD A10 PRO-7800B APU&id=2407 | R21: =IF(COUNTIF(cpus!B:B, C21)>0, "found", "Missing") -> found | S21: =IF(COUNTIF(cpus!C:C, G21)>0, "found", "Missing") -> found
A22: =IF(COUNTIF(C22,"*Quad CPU]*"),"found","missing") -> missing | B22: =IF(COUNTIF(C22,"*[Dual CPU]*"),"found","missing") -> missing | C22: =SUBSTITUTE(SUBSTITUTE(SUBSTITUTE(SUBSTITUTE(SUBSTITUTE(I22," Dual Core","")," Quad Core","")," Quad-Core","")," Dual-Core","")," APU","") -> AMD A10 PRO-7850B | D22: =IF(ISNUMBER(SEARCH("AMD",H22)),"AMD", IF(ISNUMBER(SEARCH("Intel",H22)),"Intel", IF(ISNUMBER(SEARCH("Apple",H22)),"Apple", IF(ISNUMBER(SEARCH("ARM",H22)),"ARM", IF(ISNUMBER(SEARCH("Google",H22)),"Google", IF(ISNUMBER(SEARCH("MediaTek",H22)),"MediaTek", IF(ISNUMBER(SEARCH("Qualcomm",H22)),"Qualcomm", IF(ISNUMBER(SEARCH("Samsung",H22)),"Samsung", IF(ISNUMBER(SEARCH("Snapdragon",H22)),"Snapdragon",""))))))))) -> AMD | E22: =TRIM(SUBSTITUTE(SUBSTITUTE(SUBSTITUTE(SUBSTITUTE(SUBSTITUTE(SUBSTITUTE(SUBSTITUTE(SUBSTITUTE(SUBSTITUTE(H22, "Apple",""),"ARM",""),"Google",""),"MediaTek",""),"Qualcomm",""),"Samsung",""),"Snapdragon",""),"Intel",""),"AMD","")) -> A10 PRO-7850B | F22: =TRIM(SUBSTITUTE(SUBSTITUTE(SUBSTITUTE(SUBSTITUTE(SUBSTITUTE(SUBSTITUTE(SUBSTITUTE(SUBSTITUTE(SUBSTITUTE(E22, "Core2 Extreme",""),"Core2 Quad",""),"Core2 Duo",""),"Core",""), "Pentium Gold",""),"Pentium",""), "Xeon Platinum",""),"Xeon Gold",""),"Xeon Silver","")) -> A10 PRO-7850B | G22: =TRIM(SUBSTITUTE(F22,"Xeon","")) -> A10 PRO-7850B | H22: =IFERROR(LEFT(C22, SEARCH(" @", C22) - 1), C22) -> AMD A10 PRO-7850B | I22: AMD A10 PRO-7850B APU | J22: FM2+ | K22: 3.7 GHz | L22: 4.0 GHz | M22: 4 | O22: 95 W | P22: Q4 2014 | Q22: https://www.cpubenchmark.net/cpu.php?cpu=AMD A10 PRO-7850B APU&id=2416 | R22: =IF(COUNTIF(cpus!B:B, C22)>0, "found", "Missing") -> found | S22: =IF(COUNTIF(cpus!C:C, G22)>0, "found", "Missing") -> found
A23: =IF(COUNTIF(C23,"*Quad CPU]*"),"found","missing") -> missing | B23: =IF(COUNTIF(C23,"*[Dual CPU]*"),"found","missing") -> missing | C23: =SUBSTITUTE(SUBSTITUTE(SUBSTITUTE(SUBSTITUTE(SUBSTITUTE(I23," Dual Core","")," Quad Core","")," Quad-Core","")," Dual-Core","")," APU","") -> AMD A10-4600M | D23: =IF(ISNUMBER(SEARCH("AMD",H23)),"AMD", IF(ISNUMBER(SEARCH("Intel",H23)),"Intel", IF(ISNUMBER(SEARCH("Apple",H23)),"Apple", IF(ISNUMBER(SEARCH("ARM",H23)),"ARM", IF(ISNUMBER(SEARCH("Google",H23)),"Google", IF(ISNUMBER(SEARCH("MediaTek",H23)),"MediaTek", IF(ISNUMBER(SEARCH("Qualcomm",H23)),"Qualcomm", IF(ISNUMBER(SEARCH("Samsung",H23)),"Samsung", IF(ISNUMBER(SEARCH("Snapdragon",H23)),"Snapdragon",""))))))))) -> AMD | E23: =TRIM(SUBSTITUTE(SUBSTITUTE(SUBSTITUTE(SUBSTITUTE(SUBSTITUTE(SUBSTITUTE(SUBSTITUTE(SUBSTITUTE(SUBSTITUTE(H23, "Apple",""),"ARM",""),"Google",""),"MediaTek",""),"Qualcomm",""),"Samsung",""),"Snapdragon",""),"Intel",""),"AMD","")) -> A10-4600M | F23: =TRIM(SUBSTITUTE(SUBSTITUTE(SUBSTITUTE(SUBSTITUTE(SUBSTITUTE(SUBSTITUTE(SUBSTITUTE(SUBSTITUTE(SUBSTITUTE(E23, "Core2 Extreme",""),"Core2 Quad",""),"Core2 Duo",""),"Core",""), "Pentium Gold",""),"Pentium",""), "Xeon Platinum",""),"Xeon Gold",""),"Xeon Silver","")) -> A10-4600M | G23: =TRIM(SUBSTITUTE(F23,"Xeon","")) -> A10-4600M | H23: =IFERROR(LEFT(C23, SEARCH(" @", C23) - 1), C23) -> AMD A10-4600M | I23: AMD A10-4600M APU | J23: FS1r2 | K23: 2.3 GHz | L23: 3.2 GHz | M23: 4 | O23: 35 W | P23: Q2 2012 | Q23: https://www.cpubenchmark.net/cpu.php?cpu=AMD A10-4600M APU&id=10 | R23: =IF(COUNTIF(cpus!B:B, C23)>0, "found", "Missing") -> found | S23: =IF(COUNTIF(cpus!C:C, G23)>0, "found", "Missing") -> found
A24: =IF(COUNTIF(C24,"*Quad CPU]*"),"found","missing") -> missing | B24: =IF(COUNTIF(C24,"*[Dual CPU]*"),"found","missing") -> missing | C24: =SUBSTITUTE(SUBSTITUTE(SUBSTITUTE(SUBSTITUTE(SUBSTITUTE(I24," Dual Core","")," Quad Core","")," Quad-Core","")," Dual-Core","")," APU","") -> AMD A10-4655M | D24: =IF(ISNUMBER(SEARCH("AMD",H24)),"AMD", IF(ISNUMBER(SEARCH("Intel",H24)),"Intel", IF(ISNUMBER(SEARCH("Apple",H24)),"Apple", IF(ISNUMBER(SEARCH("ARM",H24)),"ARM", IF(ISNUMBER(SEARCH("Google",H24)),"Google", IF(ISNUMBER(SEARCH("MediaTek",H24)),"MediaTek", IF(ISNUMBER(SEARCH("Qualcomm",H24)),"Qualcomm", IF(ISNUMBER(SEARCH("Samsung",H24)),"Samsung", IF(ISNUMBER(SEARCH("Snapdragon",H24)),"Snapdragon",""))))))))) -> AMD | E24: =TRIM(SUBSTITUTE(SUBSTITUTE(SUBSTITUTE(SUBSTITUTE(SUBSTITUTE(SUBSTITUTE(SUBSTITUTE(SUBSTITUTE(SUBSTITUTE(H24, "Apple",""),"ARM",""),"Google",""),"MediaTek",""),"Qualcomm",""),"Samsung",""),"Snapdragon",""),"Intel",""),"AMD","")) -> A10-4655M | F24: =TRIM(SUBSTITUTE(SUBSTITUTE(SUBSTITUTE(SUBSTITUTE(SUBSTITUTE(SUBSTITUTE(SUBSTITUTE(SUBSTITUTE(SUBSTITUTE(E24, "Core2 Extreme",""),"Core2 Quad",""),"Core2 Duo",""),"Core",""), "Pentium Gold",""),"Pentium",""), "Xeon Platinum",""),"Xeon Gold",""),"Xeon Silver","")) -> A10-4655M | G24: =TRIM(SUBSTITUTE(F24,"Xeon","")) -> A10-4655M | H24: =IFERROR(LEFT(C24, SEARCH(" @", C24) - 1), C24) -> AMD A10-4655M | I24: AMD A10-4655M APU | J24: FP2 | K24: 2.0 GHz | L24: 2.8 GHz | M24: 4 | O24: 25 W | P24: Q3 2012 | Q24: https://www.cpubenchmark.net/cpu.php?cpu=AMD A10-4655M APU&id=11 | R24: =IF(COUNTIF(cpus!B:B, C24)>0, "found", "Missing") -> found | S24: =IF(COUNTIF(cpus!C:C, G24)>0, "found", "Missing") -> found
A25: =IF(COUNTIF(C25,"*Quad CPU]*"),"found","missing") -> missing | B25: =IF(COUNTIF(C25,"*[Dual CPU]*"),"found","missing") -> missing | C25: =SUBSTITUTE(SUBSTITUTE(SUBSTITUTE(SUBSTITUTE(SUBSTITUTE(I25," Dual Core","")," Quad Core","")," Quad-Core","")," Dual-Core","")," APU","") -> AMD A10-4657M | D25: =IF(ISNUMBER(SEARCH("AMD",H25)),"AMD", IF(ISNUMBER(SEARCH("Intel",H25)),"Intel", IF(ISNUMBER(SEARCH("Apple",H25)),"Apple", IF(ISNUMBER(SEARCH("ARM",H25)),"ARM", IF(ISNUMBER(SEARCH("Google",H25)),"Google", IF(ISNUMBER(SEARCH("MediaTek",H25)),"MediaTek", IF(ISNUMBER(SEARCH("Qualcomm",H25)),"Qualcomm", IF(ISNUMBER(SEARCH("Samsung",H25)),"Samsung", IF(ISNUMBER(SEARCH("Snapdragon",H25)),"Snapdragon",""))))))))) -> AMD | E25: =TRIM(SUBSTITUTE(SUBSTITUTE(SUBSTITUTE(SUBSTITUTE(SUBSTITUTE(SUBSTITUTE(SUBSTITUTE(SUBSTITUTE(SUBSTITUTE(H25, "Apple",""),"ARM",""),"Google",""),"MediaTek",""),"Qualcomm",""),"Samsung",""),"Snapdragon",""),"Intel",""),"AMD","")) -> A10-4657M | F25: =TRIM(SUBSTITUTE(SUBSTITUTE(SUBSTITUTE(SUBSTITUTE(SUBSTITUTE(SUBSTITUTE(SUBSTITUTE(SUBSTITUTE(SUBSTITUTE(E25, "Core2 Extreme",""),"Core2 Quad",""),"Core2 Duo",""),"Core",""), "Pentium Gold",""),"Pentium",""), "Xeon Platinum",""),"Xeon Gold",""),"Xeon Silver","")) -> A10-4657M | G25: =TRIM(SUBSTITUTE(F25,"Xeon","")) -> A10-4657M | H25: =IFERROR(LEFT(C25, SEARCH(" @", C25) - 1), C25) -> AMD A10-4657M | I25: AMD A10-4657M APU | J25: FP2 | K25: 2.3 GHz | L25: 3.2 GHz | M25: 4 | O25: 35 W | P25: Q2 2013 | Q25: https://www.cpubenchmark.net/cpu.php?cpu=AMD A10-4657M APU&id=1906 | R25: =IF(COUNTIF(cpus!B:B, C25)>0, "found", "Missing") -> found | S25: =IF(COUNTIF(cpus!C:C, G25)>0, "found", "Missing") -> found
